<?xml version="1.0" encoding="utf-8"?>
<!-- This URDF was automatically created by SolidWorks to URDF Exporter! Originally created by Stephen Brawner (brawner@gmail.com) 
     Commit Version: 1.6.0-4-g7f85cfe  Build Version: 1.6.7995.38578
     For more information, please see http://wiki.ros.org/sw_urdf_exporter -->
<robot
  name="ADSAssemb_v12_lightweight">
  <link
    name="base_link">
    <inertial>
      <origin
        xyz="0.00267896883161542 -9.61752241291636E-05 0.261954730030994"
        rpy="0 0 0" />
      <mass
        value="12.9156269098643" />
      <inertia
        ixx="3.04196814982223"
        ixy="0.000208508466977494"
        ixz="-0.0119266922585532"
        iyy="8.81574617692616"
        iyz="-9.28591580220543E-05"
        izz="9.01306119890388" />
    </inertial>
    <visual>
      <origin
        xyz="0 0 0"
        rpy="0 0 0" />
      <geometry>
        <mesh
          filename="package://ADSAssemb_v12_lightweight/meshes/base_link.STL" />
      </geometry>
      <material
        name="">
        <color
          rgba="1 1 1 1" />
      </material>
    </visual>
    <collision>
      <origin
        xyz="0 0 0"
        rpy="0 0 0" />
      <geometry>
        <mesh
          filename="package://ADSAssemb_v12_lightweight/meshes/base_link.STL" />
      </geometry>
    </collision>
  </link>
  <link
    name="robotbase">
    <inertial>
      <origin
        xyz="0.00087337931461412 -1.74942310223747E-05 0.0175655883659414"
        rpy="0 0 0" />
      <mass
        value="0.0805247204958663" />
      <inertia
        ixx="0.000180322819963714"
        ixy="1.24613589460169E-08"
        ixz="-2.54790200977994E-08"
        iyy="0.0001838664383582"
        iyz="-1.33132482630703E-08"
        izz="0.000325091649240371" />
    </inertial>
    <visual>
      <origin
        xyz="0 0 0"
        rpy="0 0 0" />
      <geometry>
        <mesh
          filename="package://ADSAssemb_v12_lightweight/meshes/robotbase.STL" />
      </geometry>
      <material
        name="">
        <color
          rgba="1 1 1 1" />
      </material>
    </visual>
    <collision>
      <origin
        xyz="0 0 0"
        rpy="0 0 0" />
      <geometry>
        <mesh
          filename="package://ADSAssemb_v12_lightweight/meshes/robotbase.STL" />
      </geometry>
    </collision>
  </link>
  <joint
    name="robotbaseJ"
    type="fixed">
    <origin
      xyz="-0.195164641077713 -0.379884698907027 0"
      rpy="0 0 0" />
    <parent
      link="base_link" />
    <child
      link="robotbase" />
    <axis
      xyz="0 0 0" />
  </joint>
  <link
    name="link2">
    <inertial>
      <origin
        xyz="6.49180704758723E-05 0.0119758615957154 0.0783201526670301"
        rpy="0 0 0" />
      <mass
        value="3.7182094054082" />
      <inertia
        ixx="0.0142657255909075"
        ixy="-3.92019568605019E-06"
        ixz="-6.80126429261393E-06"
        iyy="0.0135481181792382"
        iyz="-0.00109592362499777"
        izz="0.0127628102876403" />
    </inertial>
    <visual>
      <origin
        xyz="0 0 0"
        rpy="0 0 0" />
      <geometry>
        <mesh
          filename="package://ADSAssemb_v12_lightweight/meshes/link2.STL" />
      </geometry>
      <material
        name="">
        <color
          rgba="0.294117647058824 0.294117647058824 0.294117647058824 1" />
      </material>
    </visual>
    <collision>
      <origin
        xyz="0 0 0"
        rpy="0 0 0" />
      <geometry>
        <mesh
          filename="package://ADSAssemb_v12_lightweight/meshes/link2.STL" />
      </geometry>
    </collision>
  </link>
  <joint
    name="link2J"
    type="revolute">
    <origin
      xyz="0 0 0.038"
      rpy="0 0 0" />
    <parent
      link="robotbase" />
    <child
      link="link2" />
    <axis
      xyz="0 0 -1" />
    <limit
      lower="-3.14"
      upper="3.14"
      effort="100"
      velocity="100" />
  </joint>
  <link
    name="link3">
    <inertial>
      <origin
        xyz="-0.172106891461319 0.0802101174901835 0.16641396590184"
        rpy="0 0 0" />
      <mass
        value="5.66483274765619" />
      <inertia
        ixx="0.0191701928641769"
        ixy="0.0028813792442428"
        ixz="0.000777239712019246"
        iyy="0.0236296511689338"
        iyz="-0.000223329307627467"
        izz="0.0234019280653295" />
    </inertial>
    <visual>
      <origin
        xyz="0 0 0"
        rpy="0 0 0" />
      <geometry>
        <mesh
          filename="package://ADSAssemb_v12_lightweight/meshes/link3.STL" />
      </geometry>
      <material
        name="">
        <color
          rgba="0.294117647058824 0.294117647058824 0.294117647058824 1" />
      </material>
    </visual>
    <collision>
      <origin
        xyz="0 0 0"
        rpy="0 0 0" />
      <geometry>
        <mesh
          filename="package://ADSAssemb_v12_lightweight/meshes/link3.STL" />
      </geometry>
    </collision>
  </link>
  <joint
    name="link3J"
    type="revolute">
    <origin
      xyz="0 0 0.08999999999999"
      rpy="1.5707963267949 0 3.13655830335947" />
    <parent
      link="link2" />
    <child
      link="link3" />
    <axis
      xyz="0 0 1" />
    <limit
      lower="-3.14"
      upper="3.14"
      effort="100"
      velocity="100" />
  </joint>
  <link
    name="link4">
    <inertial>
      <origin
        xyz="-0.179097550529596 0.0501407464908787 0.134749751070184"
        rpy="0 0 0" />
      <mass
        value="2.62363559938116" />
      <inertia
        ixx="0.00606738890018259"
        ixy="0.000809741423274313"
        ixz="0.00199151402947231"
        iyy="0.00923730599666288"
        iyz="-0.000611645520784777"
        izz="0.00804167132883016" />
    </inertial>
    <visual>
      <origin
        xyz="0 0 0"
        rpy="0 0 0" />
      <geometry>
        <mesh
          filename="package://ADSAssemb_v12_lightweight/meshes/link4.STL" />
      </geometry>
      <material
        name="">
        <color
          rgba="0.294117647058824 0.294117647058824 0.294117647058824 1" />
      </material>
    </visual>
    <collision>
      <origin
        xyz="0 0 0"
        rpy="0 0 0" />
      <geometry>
        <mesh
          filename="package://ADSAssemb_v12_lightweight/meshes/link4.STL" />
      </geometry>
    </collision>
  </link>
  <joint
    name="link4J"
    type="revolute">
    <origin
      xyz="-0.523314470651751 0.329959873083367 0.0798227083269905"
      rpy="0.347074183790574 0 -1.5707963267949" />
    <parent
      link="link3" />
    <child
      link="link4" />
    <axis
      xyz="0.599703956798518 0 0.800221946837376" />
    <limit
      lower="-3.14"
      upper="3.14"
      effort="100"
      velocity="100" />
  </joint>
  <link
    name="link5">
    <inertial>
      <origin
        xyz="-0.00935757510871427 -0.000463711111558351 0.108432060629465"
        rpy="0 0 0" />
      <mass
        value="0.921529845623198" />
      <inertia
        ixx="0.00112283111939906"
        ixy="-1.35455417019885E-05"
        ixz="0.000110171758385526"
        iyy="0.00139920024136962"
        iyz="5.37884270265833E-06"
        izz="0.00130723220032857" />
    </inertial>
    <visual>
      <origin
        xyz="0 0 0"
        rpy="0 0 0" />
      <geometry>
        <mesh
          filename="package://ADSAssemb_v12_lightweight/meshes/link5.STL" />
      </geometry>
      <material
        name="">
        <color
          rgba="1 1 1 1" />
      </material>
    </visual>
    <collision>
      <origin
        xyz="0 0 0"
        rpy="0 0 0" />
      <geometry>
        <mesh
          filename="package://ADSAssemb_v12_lightweight/meshes/link5.STL" />
      </geometry>
    </collision>
  </link>
  <joint
    name="link5J"
    type="revolute">
    <origin
      xyz="-0.44586758628649 0.127581802357824 0.334142992154841"
      rpy="2.61866703692973 0.624355966000279 -0.278695793511431" />
    <parent
      link="link4" />
    <child
      link="link5" />
    <axis
      xyz="0 0 -1" />
    <limit
      lower="-3.14"
      upper="3.14"
      effort="100"
      velocity="100" />
  </joint>
  <link
    name="link6">
    <inertial>
      <origin
        xyz="0.00226074967095263 -0.00909213102532902 0.108431334897546"
        rpy="0 0 0" />
      <mass
        value="0.921540940780998" />
      <inertia
        ixx="0.00138380959660478"
        ixy="6.48647334610227E-05"
        ixz="-2.65392524950653E-05"
        iyy="0.00113826187143618"
        iyz="0.000107065860656383"
        izz="0.00130718444270685" />
    </inertial>
    <visual>
      <origin
        xyz="0 0 0"
        rpy="0 0 0" />
      <geometry>
        <mesh
          filename="package://ADSAssemb_v12_lightweight/meshes/link6.STL" />
      </geometry>
      <material
        name="">
        <color
          rgba="0.294117647058824 0.294117647058824 0.294117647058824 1" />
      </material>
    </visual>
    <collision>
      <origin
        xyz="0 0 0"
        rpy="0 0 0" />
      <geometry>
        <mesh
          filename="package://ADSAssemb_v12_lightweight/meshes/link6.STL" />
      </geometry>
    </collision>
  </link>
  <joint
    name="link6J"
    type="revolute">
    <origin
      xyz="0 0 0.1157"
      rpy="-1.5707963267949 1.44784169852015 1.61998121806048" />
    <parent
      link="link5" />
    <child
      link="link6" />
    <axis
      xyz="0 0 -1" />
    <limit
      lower="-3.14"
      upper="3.14"
      effort="100"
      velocity="100" />
  </joint>
  <link
    name="endeffector">
    <inertial>
      <origin
        xyz="0.031392272485553 0.0308878521460962 0.136606569054224"
        rpy="0 0 0" />
      <mass
        value="0.201669718102086" />
      <inertia
        ixx="0.000580895599864408"
        ixy="-0.000173087632451694"
        ixz="-4.46812249576809E-06"
        iyy="0.000616984340291669"
        iyz="-4.40709101163154E-06"
        izz="0.000787359478209096" />
    </inertial>
    <visual>
      <origin
        xyz="0 0 0"
        rpy="0 0 0" />
      <geometry>
        <mesh
          filename="package://ADSAssemb_v12_lightweight/meshes/endeffector.STL" />
      </geometry>
      <material
        name="">
        <color
          rgba="1 1 1 1" />
      </material>
    </visual>
    <collision>
      <origin
        xyz="0 0 0"
        rpy="0 0 0" />
      <geometry>
        <mesh
          filename="package://ADSAssemb_v12_lightweight/meshes/endeffector.STL" />
      </geometry>
    </collision>
  </link>
  <joint
    name="endeffectorJ"
    type="revolute">
    <origin
      xyz="0 0 0.115699999999999"
      rpy="1.5707963267949 -0.670331391505515 0.243361241927746" />
    <parent
      link="link6" />
    <child
      link="endeffector" />
    <axis
      xyz="0 0 -1" />
    <limit
      lower="-3.14"
      upper="3.14"
      effort="100"
      velocity="100" />
  </joint>
  <link
    name="ef_camera">
    <inertial>
      <origin
        xyz="0.000209154959000257 -0.00192117508356715 -0.0182599292123931"
        rpy="0 0 0" />
      <mass
        value="0.0191475448793281" />
      <inertia
        ixx="7.58321502227667E-06"
        ixy="-8.27882198312831E-07"
        ixz="2.96383842398273E-09"
        iyy="1.50975264471533E-05"
        iyz="-2.72240857166775E-08"
        izz="1.58763522640746E-05" />
    </inertial>
    <visual>
      <origin
        xyz="0 0 0"
        rpy="0 0 0" />
      <geometry>
        <mesh
          filename="package://ADSAssemb_v12_lightweight/meshes/ef_camera.STL" />
      </geometry>
      <material
        name="">
        <color
          rgba="0.294117647058824 0.294117647058824 0.294117647058824 1" />
      </material>
    </visual>
    <collision>
      <origin
        xyz="0 0 0"
        rpy="0 0 0" />
      <geometry>
        <mesh
          filename="package://ADSAssemb_v12_lightweight/meshes/ef_camera.STL" />
      </geometry>
    </collision>
  </link>
  <joint
    name="ef_cameraJ"
    type="fixed">
    <origin
      xyz="-0.0531319379241199 0.0839300135376235 0.142200000000004"
      rpy="-1.57079632679489 1.46235516195487 -0.813969049196102" />
    <parent
      link="endeffector" />
    <child
      link="ef_camera" />
    <axis
      xyz="0 0 0" />
  </joint>
  <link
    name="lidar">
    <inertial>
      <origin
        xyz="2.22044604925031E-16 0 0.0630636454812754"
        rpy="0 0 0" />
      <mass
        value="0.124100201144077" />
      <inertia
        ixx="0.000589494704576671"
        ixy="-8.99114749749214E-35"
        ixz="1.3682084570574E-19"
        iyy="0.000589494704576671"
        iyz="3.42032018476106E-35"
        izz="0.000441360873360877" />
    </inertial>
    <visual>
      <origin
        xyz="0 0 0"
        rpy="0 0 0" />
      <geometry>
        <mesh
          filename="package://ADSAssemb_v12_lightweight/meshes/lidar.STL" />
      </geometry>
      <material
        name="">
        <color
          rgba="0.388235294117647 0.4 0.858823529411765 0.3" />
      </material>
    </visual>
    <collision>
      <origin
        xyz="0 0 0"
        rpy="0 0 0" />
      <geometry>
        <mesh
          filename="package://ADSAssemb_v12_lightweight/meshes/lidar.STL" />
      </geometry>
    </collision>
  </link>
  <joint
    name="lidarJ"
    type="fixed">
    <origin
      xyz="0.909835358922286 -0.000112443156507186 0.895"
      rpy="0 0 0" />
    <parent
      link="base_link" />
    <child
      link="lidar" />
    <axis
      xyz="0 0 0" />
  </joint>
  <link
    name="frontcamera">
    <inertial>
      <origin
        xyz="2.4980018054066E-16 -5.55111512312578E-17 0.000465035506435951"
        rpy="0 0 0" />
      <mass
        value="0.00868993861891032" />
      <inertia
        ixx="1.54944838856018E-06"
        ixy="-2.18427380502284E-21"
        ixz="3.47759421842166E-21"
        iyy="8.55825553887698E-06"
        iyz="6.94617513069525E-23"
        izz="9.38412024450808E-06" />
    </inertial>
    <visual>
      <origin
        xyz="0 0 0"
        rpy="0 0 0" />
      <geometry>
        <mesh
          filename="package://ADSAssemb_v12_lightweight/meshes/frontcamera.STL" />
      </geometry>
      <material
        name="">
        <color
          rgba="0.294117647058824 0.294117647058824 0.294117647058824 1" />
      </material>
    </visual>
    <collision>
      <origin
        xyz="0 0 0"
        rpy="0 0 0" />
      <geometry>
        <mesh
          filename="package://ADSAssemb_v12_lightweight/meshes/frontcamera.STL" />
      </geometry>
    </collision>
  </link>
  <joint
    name="frontcameraJ"
    type="fixed">
    <origin
      xyz="1.12451672844934 -0.000112443156507103 0.657651354832721"
      rpy="1.5707963267949 0 1.5707963267949" />
    <parent
      link="base_link" />
    <child
      link="frontcamera" />
    <axis
      xyz="0 0 0" />
  </joint>
  <link
    name="leftsidecamera">
    <inertial>
      <origin
        xyz="-0.0015006059584568 1.12663783944367E-05 0.000340964664842458"
        rpy="0 0 0" />
      <mass
        value="0.0135082472325153" />
      <inertia
        ixx="3.97017657484854E-06"
        ixy="-3.38615063503774E-11"
        ixz="9.71515400096785E-11"
        iyy="2.47347091924415E-05"
        iyz="-1.41319895230769E-07"
        izz="2.64532434955952E-05" />
    </inertial>
    <visual>
      <origin
        xyz="0 0 0"
        rpy="0 0 0" />
      <geometry>
        <mesh
          filename="package://ADSAssemb_v12_lightweight/meshes/leftsidecamera.STL" />
      </geometry>
      <material
        name="">
        <color
          rgba="0.294117647058824 0.294117647058824 0.294117647058824 1" />
      </material>
    </visual>
    <collision>
      <origin
        xyz="0 0 0"
        rpy="0 0 0" />
      <geometry>
        <mesh
          filename="package://ADSAssemb_v12_lightweight/meshes/leftsidecamera.STL" />
      </geometry>
    </collision>
  </link>
  <joint
    name="leftsidecameraJ"
    type="fixed">
    <origin
      xyz="0.874665728767983 0.609084906338769 0.70715594077481"
      rpy="1.5707963267949 -1.0471975511966 3.14159265358979" />
    <parent
      link="base_link" />
    <child
      link="leftsidecamera" />
    <axis
      xyz="0 0 0" />
  </joint>
  <link
    name="rightsidecamera">
    <inertial>
      <origin
        xyz="-0.00150059929544993 1.12661321407526E-05 0.000340961693837349"
        rpy="0 0 0" />
      <mass
        value="0.0135082450614885" />
      <inertia
        ixx="3.97017581288526E-06"
        ixy="-3.40050593766957E-11"
        ixz="9.54149464186529E-11"
        iyy="2.47347044654112E-05"
        iyz="-1.41319829578922E-07"
        izz="2.64532395295537E-05" />
    </inertial>
    <visual>
      <origin
        xyz="0 0 0"
        rpy="0 0 0" />
      <geometry>
        <mesh
          filename="package://ADSAssemb_v12_lightweight/meshes/rightsidecamera.STL" />
      </geometry>
      <material
        name="">
        <color
          rgba="0.294117647058824 0.294117647058824 0.294117647058824 1" />
      </material>
    </visual>
    <collision>
      <origin
        xyz="0 0 0"
        rpy="0 0 0" />
      <geometry>
        <mesh
          filename="package://ADSAssemb_v12_lightweight/meshes/rightsidecamera.STL" />
      </geometry>
    </collision>
  </link>
  <joint
    name="rightsidecameraJ"
    type="fixed">
    <origin
      xyz="0.876165738041346 -0.609309792651784 0.70455784850153"
      rpy="1.57079632679489 1.0471975511966 0" />
    <parent
      link="base_link" />
    <child
      link="rightsidecamera" />
    <axis
      xyz="0 0 0" />
  </joint>
  <link
    name="fender">
    <inertial>
      <origin
        xyz="0.0343473888464345 0.000879270445121927 0.072690028688893"
        rpy="0 0 0" />
      <mass
        value="1.73886900090587" />
      <inertia
        ixx="0.39907167955972"
        ixy="0.000288830302806219"
        ixz="-0.00131362514352071"
        iyy="0.980725956624126"
        iyz="-0.000226705283280241"
        izz="1.36699135010888" />
    </inertial>
    <visual>
      <origin
        xyz="0 0 0"
        rpy="0 0 0" />
      <geometry>
        <mesh
          filename="package://ADSAssemb_v12_lightweight/meshes/fender.STL" />
      </geometry>
      <material
        name="">
        <color
          rgba="0.968627450980392 0.87843137254902 0.6 1" />
      </material>
    </visual>
    <collision>
      <origin
        xyz="0 0 0"
        rpy="0 0 0" />
      <geometry>
        <mesh
          filename="package://ADSAssemb_v12_lightweight/meshes/fender.STL" />
      </geometry>
    </collision>
  </link>
  <joint
    name="fenderJ"
    type="fixed">
    <origin
      xyz="-0.000164641077713884 -0.000112443156510628 -0.1"
      rpy="3.14159265358979 0 0" />
    <parent
      link="base_link" />
    <child
      link="fender" />
    <axis
      xyz="0 0 0" />
  </joint>
  <link
    name="frontdash">
    <inertial>
      <origin
        xyz="1.23816009883204E-05 0.399999889839718 0.0495559270838577"
        rpy="0 0 0" />
      <mass
        value="2.04998203915906" />
      <inertia
        ixx="0.268874958959614"
        ixy="-1.70913080792638E-10"
        ixz="-6.78311744935482E-07"
        iyy="0.268875017147561"
        iyz="7.52455441452148E-09"
        izz="0.527426787953778" />
    </inertial>
    <visual>
      <origin
        xyz="0 0 0"
        rpy="0 0 0" />
      <geometry>
        <mesh
          filename="package://ADSAssemb_v12_lightweight/meshes/frontdash.STL" />
      </geometry>
      <material
        name="">
        <color
          rgba="0.968627450980392 0.87843137254902 0.6 1" />
      </material>
    </visual>
    <collision>
      <origin
        xyz="0 0 0"
        rpy="0 0 0" />
      <geometry>
        <mesh
          filename="package://ADSAssemb_v12_lightweight/meshes/frontdash.STL" />
      </geometry>
    </collision>
  </link>
  <joint
    name="frontdashJ"
    type="fixed">
    <origin
      xyz="0.999835358922287 -0.000112443156510211 -0.1"
      rpy="1.5707963267949 0 1.5707963267949" />
    <parent
      link="base_link" />
    <child
      link="frontdash" />
    <axis
      xyz="0 0 0" />
  </joint>
  <link
    name="frontsection">
    <inertial>
      <origin
        xyz="-0.009748208099012 0.071697167880574 0.00448461689764645"
        rpy="0 0 0" />
      <mass
        value="1.02190700784692" />
      <inertia
        ixx="0.0668494658912585"
        ixy="1.9372337761806E-05"
        ixz="-1.45006174712553E-06"
        iyy="0.0657309814668282"
        iyz="0.000666669719171432"
        izz="0.132475182922645" />
    </inertial>
    <visual>
      <origin
        xyz="0 0 0"
        rpy="0 0 0" />
      <geometry>
        <mesh
          filename="package://ADSAssemb_v12_lightweight/meshes/frontsection.STL" />
      </geometry>
      <material
        name="">
        <color
          rgba="0.388235294117647 0.858823529411765 0.388235294117647 0.6" />
      </material>
    </visual>
    <collision>
      <origin
        xyz="0 0 0"
        rpy="0 0 0" />
      <geometry>
        <mesh
          filename="package://ADSAssemb_v12_lightweight/meshes/frontsection.STL" />
      </geometry>
    </collision>
  </link>
  <joint
    name="frontsectionJ"
    type="fixed">
    <origin
      xyz="0.0099111692635078 0.317168369090463 0.112"
      rpy="0 0 0" />
    <parent
      link="frontdash" />
    <child
      link="frontsection" />
    <axis
      xyz="0 0 0" />
  </joint>
  <link
    name="frontleftaxle">
    <inertial>
      <origin
        xyz="2.35086812583329E-06 0.169698196210335 0.00256119151789669"
        rpy="0 0 0" />
      <mass
        value="0.0892526682073699" />
      <inertia
        ixx="0.000993551567216821"
        ixy="4.24299642966238E-08"
        ixz="-5.77071925820798E-08"
        iyy="8.21828007679809E-05"
        iyz="-3.00178801744965E-05"
        izz="0.000985627081758349" />
    </inertial>
    <visual>
      <origin
        xyz="0 0 0"
        rpy="0 0 0" />
      <geometry>
        <mesh
          filename="package://ADSAssemb_v12_lightweight/meshes/frontleftaxle.STL" />
      </geometry>
      <material
        name="">
        <color
          rgba="1 1 1 1" />
      </material>
    </visual>
    <collision>
      <origin
        xyz="0 0 0"
        rpy="0 0 0" />
      <geometry>
        <mesh
          filename="package://ADSAssemb_v12_lightweight/meshes/frontleftaxle.STL" />
      </geometry>
    </collision>
  </link>
  <joint
    name="frontleftaxleJ"
    type="revolute">
    <origin
      xyz="0.639835358922285 0.344887556843492 -0.0940000000000002"
      rpy="-1.5707963267949 0 0" />
    <parent
      link="base_link" />
    <child
      link="frontleftaxle" />
    <axis
      xyz="0 1 0" />
    <limit
      lower="-1.5"
      upper="1.5"
      effort="100"
      velocity="100" />
  </joint>
  <link
    name="frontleftwheel">
    <inertial>
      <origin
        xyz="0.114473862985988 4.01437219577083E-08 -2.03833881884385E-07"
        rpy="0 0 0" />
      <mass
        value="0.798561900795074" />
      <inertia
        ixx="0.0301385005512154"
        ixy="1.01220610649959E-11"
        ixz="2.33394343278393E-11"
        iyy="0.018990826798765"
        iyz="3.90823545401431E-11"
        izz="0.0189908273455703" />
    </inertial>
    <visual>
      <origin
        xyz="0 0 0"
        rpy="0 0 0" />
      <geometry>
        <mesh
          filename="package://ADSAssemb_v12_lightweight/meshes/frontleftwheel.STL" />
      </geometry>
      <material
        name="">
        <color
          rgba="0.294117647058824 0.294117647058824 0.294117647058824 1" />
      </material>
    </visual>
    <collision>
      <origin
        xyz="0 0 0"
        rpy="0 0 0" />
      <geometry>
        <mesh
          filename="package://ADSAssemb_v12_lightweight/meshes/frontleftwheel.STL" />
      </geometry>
    </collision>
  </link>
  <joint
    name="frontleftwheelJ"
    type="continuous">
    <origin
      xyz="0 0.3 0.0394304138974926"
      rpy="1.12073190059369 -1.5707963267949 0" />
    <parent
      link="frontleftaxle" />
    <child
      link="frontleftwheel" />
    <axis
      xyz="1 0 0" />
    <limit
      effort="10"
      velocity="1000" />
  </joint>
  <link
    name="frontrightaxle">
    <inertial>
      <origin
        xyz="2.35086812672147E-06 -0.169698196210334 -0.00256119151789706"
        rpy="0 0 0" />
      <mass
        value="0.0892526682073641" />
      <inertia
        ixx="0.000993551567216787"
        ixy="-4.24299642978994E-08"
        ixz="5.7707192582384E-08"
        iyy="8.2182800767978E-05"
        iyz="-3.00178801744981E-05"
        izz="0.000985627081758313" />
    </inertial>
    <visual>
      <origin
        xyz="0 0 0"
        rpy="0 0 0" />
      <geometry>
        <mesh
          filename="package://ADSAssemb_v12_lightweight/meshes/frontrightaxle.STL" />
      </geometry>
      <material
        name="">
        <color
          rgba="1 1 1 1" />
      </material>
    </visual>
    <collision>
      <origin
        xyz="0 0 0"
        rpy="0 0 0" />
      <geometry>
        <mesh
          filename="package://ADSAssemb_v12_lightweight/meshes/frontrightaxle.STL" />
      </geometry>
    </collision>
  </link>
  <joint
    name="frontrightaxleJ"
    type="revolute">
    <origin
      xyz="0.639835358922287 -0.345112443156508 -0.0939999999999998"
      rpy="1.5707963267949 0 3.14159265358979" />
    <parent
      link="base_link" />
    <child
      link="frontrightaxle" />
    <axis
      xyz="0 1 0" />
    <limit
      lower="-1.5"
      upper="1.5"
      effort="100"
      velocity="100" />
  </joint>
  <link
    name="frontrightwheel">
    <inertial>
      <origin
        xyz="0.114474043520639 1.16848695497218E-07 -2.97726304054891E-07"
        rpy="0 0 0" />
      <mass
        value="0.79855508316406" />
      <inertia
        ixx="0.0301385005512141"
        ixy="2.05944993209584E-12"
        ixz="-2.53563969889581E-11"
        iyy="0.018990826887521"
        iyz="-2.05383265082515E-10"
        izz="0.0189908272568125" />
    </inertial>
    <visual>
      <origin
        xyz="0 0 0"
        rpy="0 0 0" />
      <geometry>
        <mesh
          filename="package://ADSAssemb_v12_lightweight/meshes/frontrightwheel.STL" />
      </geometry>
      <material
        name="">
        <color
          rgba="0.294117647058824 0.294117647058824 0.294117647058824 1" />
      </material>
    </visual>
    <collision>
      <origin
        xyz="0 0 0"
        rpy="0 0 0" />
      <geometry>
        <mesh
          filename="package://ADSAssemb_v12_lightweight/meshes/frontrightwheel.STL" />
      </geometry>
    </collision>
  </link>
  <joint
    name="frontrightwheelJ"
    type="continuous">
    <origin
      xyz="0 -0.3 -0.0394304138974929"
      rpy="0.186425012387561 1.5707963267949 0" />
    <parent
      link="frontrightaxle" />
    <child
      link="frontrightwheel" />
    <axis
      xyz="1 0 0" />
    <limit
      effort="10"
      velocity="1000" />
  </joint>
  <link
    name="rearleftaxle">
    <inertial>
      <origin
        xyz="2.35086812638841E-06 0.169698196210335 0.00256119151789735"
        rpy="0 0 0" />
      <mass
        value="0.0892526682073664" />
      <inertia
        ixx="0.000993551567216794"
        ixy="4.24299643020811E-08"
        ixz="-5.77071925823229E-08"
        iyy="8.21828007679784E-05"
        iyz="-3.00178801744979E-05"
        izz="0.000985627081758321" />
    </inertial>
    <visual>
      <origin
        xyz="0 0 0"
        rpy="0 0 0" />
      <geometry>
        <mesh
          filename="package://ADSAssemb_v12_lightweight/meshes/rearleftaxle.STL" />
      </geometry>
      <material
        name="">
        <color
          rgba="1 1 1 1" />
      </material>
    </visual>
    <collision>
      <origin
        xyz="0 0 0"
        rpy="0 0 0" />
      <geometry>
        <mesh
          filename="package://ADSAssemb_v12_lightweight/meshes/rearleftaxle.STL" />
      </geometry>
    </collision>
  </link>
  <joint
    name="rearleftaxleJ"
    type="revolute">
    <origin
      xyz="-0.600164641077715 0.344887556843487 -0.094"
      rpy="-1.5707963267949 0 0" />
    <parent
      link="base_link" />
    <child
      link="rearleftaxle" />
    <axis
      xyz="0 1 0" />
    <limit
      lower="-1.5"
      upper="1.5"
      effort="100"
      velocity="100" />
  </joint>
  <link
    name="rearleftwheel">
    <inertial>
      <origin
        xyz="0.114474043515976 3.02608848645747E-07 2.87576701341052E-08"
        rpy="0 0 0" />
      <mass
        value="0.798555083174921" />
      <inertia
        ixx="0.0301385005512152"
        ixy="2.05947709155609E-12"
        ixz="-2.53564064956241E-11"
        iyy="0.0189908268875215"
        iyz="-2.05383295657016E-10"
        izz="0.0189908272568135" />
    </inertial>
    <visual>
      <origin
        xyz="0 0 0"
        rpy="0 0 0" />
      <geometry>
        <mesh
          filename="package://ADSAssemb_v12_lightweight/meshes/rearleftwheel.STL" />
      </geometry>
      <material
        name="">
        <color
          rgba="0.294117647058824 0.294117647058824 0.294117647058824 1" />
      </material>
    </visual>
    <collision>
      <origin
        xyz="0 0 0"
        rpy="0 0 0" />
      <geometry>
        <mesh
          filename="package://ADSAssemb_v12_lightweight/meshes/rearleftwheel.STL" />
      </geometry>
    </collision>
  </link>
  <joint
    name="rearleftwheelJ"
    type="continuous">
    <origin
      xyz="0 0.3 0.039430413897493"
      rpy="1.44787673373564 -1.5707963267949 0" />
    <parent
      link="rearleftaxle" />
    <child
      link="rearleftwheel" />
    <axis
      xyz="1 0 0" />
    <limit
      effort="10"
      velocity="1000" />
  </joint>
  <link
    name="rearrightaxle">
    <inertial>
      <origin
        xyz="2.35086812594432E-06 -0.169698196210335 -0.00256119151789616"
        rpy="0 0 0" />
      <mass
        value="0.089252668207366" />
      <inertia
        ixx="0.000993551567216806"
        ixy="-4.24299642997305E-08"
        ixz="5.77071925834722E-08"
        iyy="8.21828007679797E-05"
        iyz="-3.00178801744968E-05"
        izz="0.000985627081758333" />
    </inertial>
    <visual>
      <origin
        xyz="0 0 0"
        rpy="0 0 0" />
      <geometry>
        <mesh
          filename="package://ADSAssemb_v12_lightweight/meshes/rearrightaxle.STL" />
      </geometry>
      <material
        name="">
        <color
          rgba="1 1 1 1" />
      </material>
    </visual>
    <collision>
      <origin
        xyz="0 0 0"
        rpy="0 0 0" />
      <geometry>
        <mesh
          filename="package://ADSAssemb_v12_lightweight/meshes/rearrightaxle.STL" />
      </geometry>
    </collision>
  </link>
  <joint
    name="rearrightaxleJ"
    type="revolute">
    <origin
      xyz="-0.600164641077713 -0.345112443156513 -0.094"
      rpy="1.5707963267949 0 3.14159265358979" />
    <parent
      link="base_link" />
    <child
      link="rearrightaxle" />
    <axis
      xyz="0 1 0" />
    <limit
      lower="-1.5"
      upper="1.5"
      effort="100"
      velocity="100" />
  </joint>
  <link
    name="rearrightwheel">
    <inertial>
      <origin
        xyz="0.11447396607814 3.21161142124993E-09 2.53649400594469E-07"
        rpy="0 0 0" />
      <mass
        value="0.798558339436991" />
      <inertia
        ixx="0.0301385005512153"
        ixy="2.0594408200647E-12"
        ixz="-2.53564084343584E-11"
        iyy="0.0189908268875215"
        iyz="-2.0538317791266E-10"
        izz="0.0189908272568137" />
    </inertial>
    <visual>
      <origin
        xyz="0 0 0"
        rpy="0 0 0" />
      <geometry>
        <mesh
          filename="package://ADSAssemb_v12_lightweight/meshes/rearrightwheel.STL" />
      </geometry>
      <material
        name="">
        <color
          rgba="0.294117647058824 0.294117647058824 0.294117647058824 1" />
      </material>
    </visual>
    <collision>
      <origin
        xyz="0 0 0"
        rpy="0 0 0" />
      <geometry>
        <mesh
          filename="package://ADSAssemb_v12_lightweight/meshes/rearrightwheel.STL" />
      </geometry>
    </collision>
  </link>
  <joint
    name="rearrightwheelJ"
    type="continuous">
    <origin
      xyz="0 -0.3 -0.039430413897493"
      rpy="0.212725672040108 1.5707963267949 0" />
    <parent
      link="rearrightaxle" />
    <child
      link="rearrightwheel" />
    <axis
      xyz="1 0 0" />
    <limit
      effort="10"
      velocity="1000" />
  </joint>
  <link
    name="pkg1">
    <inertial>
      <origin
        xyz="0.14 0 -2.60208521396521E-18"
        rpy="0 0 0" />
      <mass
        value="15.456" />
      <inertia
        ixx="0.142324"
        ixy="7.0838528903557E-18"
        ixz="3.46944695195361E-18"
        iyy="0.175168"
        iyz="-2.01302962337938E-18"
        izz="0.1691144" />
    </inertial>
    <visual>
      <origin
        xyz="0 0 0"
        rpy="0 0 0" />
      <geometry>
        <mesh
          filename="package://ADSAssemb_v12_lightweight/meshes/pkg1.STL" />
      </geometry>
      <material
        name="">
        <color
          rgba="0.792156862745098 0.819607843137255 0.933333333333333 1" />
      </material>
    </visual>
    <collision>
      <origin
        xyz="0 0 0"
        rpy="0 0 0" />
      <geometry>
        <mesh
          filename="package://ADSAssemb_v12_lightweight/meshes/pkg1.STL" />
      </geometry>
    </collision>
  </link>
  <joint
    name="pkg1J"
    type="fixed">
    <origin
      xyz="0.709835358922287 0.0248875568434898 0.41"
      rpy="0 0 0" />
    <parent
      link="base_link" />
    <child
      link="pkg1" />
    <axis
      xyz="0 0 0" />
  </joint>
  <link
    name="pkgT2">
    <inertial>
      <origin
        xyz="0.14 0 1.11022302462516E-16"
        rpy="0 0 0" />
      <mass
        value="28.224" />
      <inertia
        ixx="0.550368"
        ixy="-2.42861286636753E-17"
        ixz="2.08166817117217E-17"
        iyy="0.319872"
        iyz="1.61907524424502E-17"
        izz="0.5992896" />
    </inertial>
    <visual>
      <origin
        xyz="0 0 0"
        rpy="0 0 0" />
      <geometry>
        <mesh
          filename="package://ADSAssemb_v12_lightweight/meshes/pkgT2.STL" />
      </geometry>
      <material
        name="">
        <color
          rgba="0.792156862745098 0.819607843137255 0.933333333333333 1" />
      </material>
    </visual>
    <collision>
      <origin
        xyz="0 0 0"
        rpy="0 0 0" />
      <geometry>
        <mesh
          filename="package://ADSAssemb_v12_lightweight/meshes/pkgT2.STL" />
      </geometry>
    </collision>
  </link>
  <joint
    name="pkgT2J"
    type="fixed">
    <origin
      xyz="0.709835358922287 0.23488755684349 0.14"
      rpy="0 0 0" />
    <parent
      link="base_link" />
    <child
      link="pkgT2" />
    <axis
      xyz="0 0 0" />
  </joint>
</robot>